<?xml version="1.0" ?>
<robot name="sf_bot" xmlns:xacro="http://www.ros.org/wiki/xacro">

<xacro:include filename="$(find sf_bot_description)/urdf/materials.xacro" />
<xacro:include filename="$(find sf_bot_description)/urdf/sf_bot.trans" />
<xacro:include filename="$(find sf_bot_description)/urdf/sf_bot.gazebo" />
<link name="base_link">
  <inertial>
    <origin xyz="0.00011931762984611134 5.725071583357913e-07 0.107864507793266" rpy="0 0 0"/>
    <mass value="0.9950315859189844"/>
    <inertia ixx="0.013071" iyy="0.011583" izz="0.007665" ixy="1e-06" iyz="0.0" ixz="-1e-05"/>
  </inertial>
  <visual>
    <origin xyz="0 0 0" rpy="0 0 0"/>
    <geometry>
      <mesh filename="file://$(find sf_bot_description)/meshes/base_link.stl" scale="0.001 0.001 0.001"/>
    </geometry>
    <material name="silver"/>
  </visual>
  <collision>
    <origin xyz="0 0 0" rpy="0 0 0"/>
    <geometry>
      <mesh filename="file://$(find sf_bot_description)/meshes/base_link.stl" scale="0.001 0.001 0.001"/>
    </geometry>
  </collision>
</link>

<link name="motor_right_1">
  <inertial>
    <origin xyz="-1.0196434290534508e-06 0.0020948107094494323 -0.021749702787001394" rpy="0 0 0"/>
    <mass value="0.40922971045827883"/>
    <inertia ixx="0.000176" iyy="6.3e-05" izz="0.000172" ixy="-0.0" iyz="-1e-06" ixz="-0.0"/>
  </inertial>
  <visual>
    <origin xyz="-1e-06 0.075002 -0.0" rpy="0 0 0"/>
    <geometry>
      <mesh filename="file://$(find sf_bot_description)/meshes/motor_right_1.stl" scale="0.001 0.001 0.001"/>
    </geometry>
    <material name="silver"/>
  </visual>
  <collision>
    <origin xyz="-1e-06 0.075002 -0.0" rpy="0 0 0"/>
    <geometry>
      <mesh filename="file://$(find sf_bot_description)/meshes/motor_right_1.stl" scale="0.001 0.001 0.001"/>
    </geometry>
  </collision>
</link>

<link name="motor_left_1">
  <inertial>
    <origin xyz="-1.0196434290782216e-06 -0.0020948107094494184 -0.0217497027870014" rpy="0 0 0"/>
    <mass value="0.40922971045827883"/>
    <inertia ixx="0.000176" iyy="6.3e-05" izz="0.000172" ixy="0.0" iyz="1e-06" ixz="-0.0"/>
  </inertial>
  <visual>
    <origin xyz="-1e-06 -0.075002 -0.0" rpy="0 0 0"/>
    <geometry>
      <mesh filename="file://$(find sf_bot_description)/meshes/motor_left_1.stl" scale="0.001 0.001 0.001"/>
    </geometry>
    <material name="silver"/>
  </visual>
  <collision>
    <origin xyz="-1e-06 -0.075002 -0.0" rpy="0 0 0"/>
    <geometry>
      <mesh filename="file://$(find sf_bot_description)/meshes/motor_left_1.stl" scale="0.001 0.001 0.001"/>
    </geometry>
  </collision>
</link>

<link name="imu_link_1">
  <inertial>
    <origin xyz="0.0 0.0 -0.00165" rpy="0 0 0"/>
    <mass value="0.0090066504"/>
    <inertia ixx="0.0" iyy="0.0" izz="1e-06" ixy="0.0" iyz="-0.0" ixz="-0.0"/>
  </inertial>
  <visual>
    <origin xyz="-0.0 -0.0 -0.0" rpy="0 0 0"/>
    <geometry>
      <mesh filename="file://$(find sf_bot_description)/meshes/imu_link_1.stl" scale="0.001 0.001 0.001"/>
    </geometry>
    <material name="silver"/>
  </visual>
  <collision>
    <origin xyz="-0.0 -0.0 -0.0" rpy="0 0 0"/>
    <geometry>
      <mesh filename="file://$(find sf_bot_description)/meshes/imu_link_1.stl" scale="0.001 0.001 0.001"/>
    </geometry>
  </collision>
</link>

<link name="motor_driver_1">
  <inertial>
    <origin xyz="0.0001036913880996842 -0.004835776222540905 0.001964330363631306" rpy="0 0 0"/>
    <mass value="0.10665515793282898"/>
    <inertia ixx="6.5e-05" iyy="2.8e-05" izz="9.2e-05" ixy="0.0" iyz="2e-06" ixz="-0.0"/>
  </inertial>
  <visual>
    <origin xyz="-0.0 -0.0 -0.008" rpy="0 0 0"/>
    <geometry>
      <mesh filename="file://$(find sf_bot_description)/meshes/motor_driver_1.stl" scale="0.001 0.001 0.001"/>
    </geometry>
    <material name="silver"/>
  </visual>
  <collision>
    <origin xyz="-0.0 -0.0 -0.008" rpy="0 0 0"/>
    <geometry>
      <mesh filename="file://$(find sf_bot_description)/meshes/motor_driver_1.stl" scale="0.001 0.001 0.001"/>
    </geometry>
  </collision>
</link>

<link name="node_mcu_1">
  <inertial>
    <origin xyz="0.0023749741999873767 4.290503520520961e-08 0.0011611203050715911" rpy="0 0 0"/>
    <mass value="0.004427527956579565"/>
    <inertia ixx="0.0" iyy="0.0" izz="0.0" ixy="0.0" iyz="0.0" ixz="-0.0"/>
  </inertial>
  <visual>
    <origin xyz="-0.002051 -0.075002 -0.008" rpy="0 0 0"/>
    <geometry>
      <mesh filename="file://$(find sf_bot_description)/meshes/node_mcu_1.stl" scale="0.001 0.001 0.001"/>
    </geometry>
    <material name="silver"/>
  </visual>
  <collision>
    <origin xyz="-0.002051 -0.075002 -0.008" rpy="0 0 0"/>
    <geometry>
      <mesh filename="file://$(find sf_bot_description)/meshes/node_mcu_1.stl" scale="0.001 0.001 0.001"/>
    </geometry>
  </collision>
</link>

<link name="li_ion_battery_1">
  <inertial>
    <origin xyz="0.0011956362304908772 -7.000827092053241e-05 0.0029366620313676928" rpy="0 0 0"/>
    <mass value="0.034962326993171845"/>
    <inertia ixx="2e-06" iyy="3e-06" izz="5e-06" ixy="0.0" iyz="0.0" ixz="-0.0"/>
  </inertial>
  <visual>
    <origin xyz="-1e-06 0.075002 -0.008" rpy="0 0 0"/>
    <geometry>
      <mesh filename="file://$(find sf_bot_description)/meshes/li_ion_battery_1.stl" scale="0.001 0.001 0.001"/>
    </geometry>
    <material name="silver"/>
  </visual>
  <collision>
    <origin xyz="-1e-06 0.075002 -0.008" rpy="0 0 0"/>
    <geometry>
      <mesh filename="file://$(find sf_bot_description)/meshes/li_ion_battery_1.stl" scale="0.001 0.001 0.001"/>
    </geometry>
  </collision>
</link>

<link name="top_base_1">
  <inertial>
    <origin xyz="-0.08143284697619828 0.1013870830223493 0.20797423368380727" rpy="0 0 0"/>
    <mass value="0.7916231280930065"/>
    <inertia ixx="0.01404" iyy="0.011997" izz="0.007394" ixy="2e-06" iyz="-1e-06" ixz="-2e-06"/>
  </inertial>
  <visual>
    <origin xyz="-0.081414 0.101414 -0.216" rpy="0 0 0"/>
    <geometry>
      <mesh filename="file://$(find sf_bot_description)/meshes/top_base_1.stl" scale="0.001 0.001 0.001"/>
    </geometry>
    <material name="silver"/>
  </visual>
  <collision>
    <origin xyz="-0.081414 0.101414 -0.216" rpy="0 0 0"/>
    <geometry>
      <mesh filename="file://$(find sf_bot_description)/meshes/top_base_1.stl" scale="0.001 0.001 0.001"/>
    </geometry>
  </collision>
</link>

<link name="right_wheel_1">
  <inertial>
    <origin xyz="2.952122497918742e-07 0.00215796946669089 2.5919413156050286e-07" rpy="0 0 0"/>
    <mass value="1.020798021407396"/>
    <inertia ixx="0.000884" iyy="0.00167" izz="0.000884" ixy="0.0" iyz="0.0" ixz="0.0"/>
  </inertial>
  <visual>
    <origin xyz="1.2e-05 0.1322 0.029064" rpy="0 0 0"/>
    <geometry>
      <mesh filename="file://$(find sf_bot_description)/meshes/right_wheel_1.stl" scale="0.001 0.001 0.001"/>
    </geometry>
    <material name="silver"/>
  </visual>
  <collision>
    <origin xyz="1.2e-05 0.1322 0.029064" rpy="0 0 0"/>
    <geometry>
      <mesh filename="file://$(find sf_bot_description)/meshes/right_wheel_1.stl" scale="0.001 0.001 0.001"/>
    </geometry>
  </collision>
</link>

<link name="left_wheel_1">
  <inertial>
    <origin xyz="2.952122374692592e-07 -0.0021579694666909455 2.5919412152339283e-07" rpy="0 0 0"/>
    <mass value="1.0207980214073975"/>
    <inertia ixx="0.000884" iyy="0.00167" izz="0.000884" ixy="-0.0" iyz="-0.0" ixz="-0.0"/>
  </inertial>
  <visual>
    <origin xyz="1.2e-05 -0.1322 0.029064" rpy="0 0 0"/>
    <geometry>
      <mesh filename="file://$(find sf_bot_description)/meshes/left_wheel_1.stl" scale="0.001 0.001 0.001"/>
    </geometry>
    <material name="silver"/>
  </visual>
  <collision>
    <origin xyz="1.2e-05 -0.1322 0.029064" rpy="0 0 0"/>
    <geometry>
      <mesh filename="file://$(find sf_bot_description)/meshes/left_wheel_1.stl" scale="0.001 0.001 0.001"/>
    </geometry>
  </collision>
</link>

<joint name="Rigid 1" type="fixed">
  <origin xyz="1e-06 -0.075002 0.0" rpy="0 0 0"/>
  <parent link="base_link"/>
  <child link="motor_right_1"/>
</joint>

<joint name="Rigid 2" type="fixed">
  <origin xyz="1e-06 0.075002 0.0" rpy="0 0 0"/>
  <parent link="base_link"/>
  <child link="motor_left_1"/>
</joint>

<joint name="Rigid 3" type="fixed">
  <origin xyz="0.0 0.0 0.0" rpy="0 0 0"/>
  <parent link="base_link"/>
  <child link="imu_link_1"/>
</joint>

<joint name="Rigid 4" type="fixed">
  <origin xyz="0.0 0.0 0.008" rpy="0 0 0"/>
  <parent link="base_link"/>
  <child link="motor_driver_1"/>
</joint>

<joint name="Rigid 5" type="fixed">
  <origin xyz="0.002051 0.075002 0.008" rpy="0 0 0"/>
  <parent link="base_link"/>
  <child link="node_mcu_1"/>
</joint>

<joint name="Rigid 6" type="fixed">
  <origin xyz="1e-06 -0.075002 0.008" rpy="0 0 0"/>
  <parent link="base_link"/>
  <child link="li_ion_battery_1"/>
</joint>

<joint name="Rigid 7" type="fixed">
  <origin xyz="0.081414 -0.101414 0.216" rpy="0 0 0"/>
  <parent link="base_link"/>
  <child link="top_base_1"/>
</joint>

<joint name="left_wheel_joint" type="continuous">
  <origin xyz="-1.3e-05 -0.057198 -0.029064" rpy="0 0 0"/>
  <parent link="motor_right_1"/>
  <child link="right_wheel_1"/>
  <axis xyz="-0.000205 -1.0 -0.0"/>
</joint>

<joint name="right_wheel_joint" type="continuous">
  <origin xyz="-1.3e-05 0.057198 -0.029064" rpy="0 0 0"/>
  <parent link="motor_left_1"/>
  <child link="left_wheel_1"/>
  <axis xyz="0.000205 -1.0 0.0"/>
</joint>

</robot>
